2024-03-01 14:03:03,858 INFO    MainThread:33764 [internal.py:wandb_internal():62] W&B internal server running at pid: 33764
2024-03-01 14:03:03,858 INFO    WriterThread:33764 [datastore.py:open_for_write():76] open: C:\Users\aplus\macbf\drones\drones\method\on-policy\onpolicy\scripts\results\MPE\simple_speaker_listener\rmappo\check\wandb\run-20240301_140302-28stht8q\run-28stht8q.wandb
2024-03-01 14:03:03,858 DEBUG   HandlerThread:33764 [handler.py:handle_request():54] handle_request: check_version
2024-03-01 14:03:03,858 DEBUG   SenderThread:33764 [sender.py:send():88] send: header
2024-03-01 14:03:03,858 DEBUG   SenderThread:33764 [sender.py:send():88] send: request
2024-03-01 14:03:03,858 DEBUG   SenderThread:33764 [sender.py:send_request():97] send_request: check_version
2024-03-01 14:03:03,865 DEBUG   Thread-8  :33764 [connectionpool.py:_new_conn():823] Starting new HTTPS connection (1): pypi.org:443
2024-03-01 14:03:04,254 DEBUG   Thread-8  :33764 [connectionpool.py:_make_request():393] https://pypi.org:443 "GET /pypi/wandb/json HTTP/1.1" 200 81401
2024-03-01 14:03:04,344 DEBUG   SenderThread:33764 [sender.py:send():88] send: run
2024-03-01 14:03:04,379 DEBUG   SenderThread:33764 [util.py:is_cygwin_git():315] Failed checking if running in CYGWIN due to: FileNotFoundError(2, 'The system cannot find the file specified', None, 2, None)
2024-03-01 14:03:04,386 DEBUG   SenderThread:33764 [cmd.py:execute():719] Popen(['git', 'cat-file', '--batch-check'], cwd=C:\Users\aplus\macbf\drones\drones, universal_newlines=False, shell=None, istream=<valid stream>)
2024-03-01 14:03:04,448 DEBUG   SenderThread:33764 [connectionpool.py:_new_conn():823] Starting new HTTPS connection (1): api.wandb.ai:443
2024-03-01 14:03:04,796 DEBUG   SenderThread:33764 [connectionpool.py:_make_request():393] https://api.wandb.ai:443 "POST /graphql HTTP/1.1" 401 None
2024-03-01 14:03:04,796 ERROR   SenderThread:33764 [internal_api.py:execute():131] 401 response executing GraphQL.
2024-03-01 14:03:04,796 ERROR   SenderThread:33764 [internal_api.py:execute():132] {"errors":[{"message":"user is not logged in","path":["upsertBucket"],"extensions":{"code":"PERMISSION_ERROR"}}],"data":{"upsertBucket":null}}
2024-03-01 14:03:05,351 INFO    WriterThread:33764 [datastore.py:close():257] close: C:\Users\aplus\macbf\drones\drones\method\on-policy\onpolicy\scripts\results\MPE\simple_speaker_listener\rmappo\check\wandb\run-20240301_140302-28stht8q\run-28stht8q.wandb
2024-03-01 14:03:05,351 INFO    HandlerThread:33764 [handler.py:finish():267] shutting down handler
2024-03-01 14:03:05,351 ERROR   MainThread:33764 [internal.py:wandb_internal():128] Thread SenderThread:
Traceback (most recent call last):
  File "D:\Anaconda\envs\onp\lib\site-packages\wandb\old\retry.py", line 96, in __call__
    result = self._call_fn(*args, **kwargs)
  File "D:\Anaconda\envs\onp\lib\site-packages\wandb\internal\internal_api.py", line 134, in execute
    six.reraise(*sys.exc_info())
  File "D:\Anaconda\envs\onp\lib\site-packages\six.py", line 703, in reraise
    raise value
  File "D:\Anaconda\envs\onp\lib\site-packages\wandb\internal\internal_api.py", line 128, in execute
    return self.client.execute(*args, **kwargs)
  File "D:\Anaconda\envs\onp\lib\site-packages\wandb\vendor\gql-0.2.0\gql\client.py", line 52, in execute
    result = self._get_result(document, *args, **kwargs)
  File "D:\Anaconda\envs\onp\lib\site-packages\wandb\vendor\gql-0.2.0\gql\client.py", line 60, in _get_result
    return self.transport.execute(document, *args, **kwargs)
  File "D:\Anaconda\envs\onp\lib\site-packages\wandb\vendor\gql-0.2.0\gql\transport\requests.py", line 39, in execute
    request.raise_for_status()
  File "D:\Anaconda\envs\onp\lib\site-packages\requests\models.py", line 941, in raise_for_status
    raise HTTPError(http_error_msg, response=self)
requests.exceptions.HTTPError: 401 Client Error: Unauthorized for url: https://api.wandb.ai/graphql

During handling of the above exception, another exception occurred:

Traceback (most recent call last):
  File "D:\Anaconda\envs\onp\lib\site-packages\wandb\apis\normalize.py", line 24, in wrapper
    return func(*args, **kwargs)
  File "D:\Anaconda\envs\onp\lib\site-packages\wandb\internal\internal_api.py", line 968, in upsert_run
    response = self.gql(mutation, variable_values=variable_values, **kwargs)
  File "D:\Anaconda\envs\onp\lib\site-packages\wandb\old\retry.py", line 105, in __call__
    if not check_retry_fn(e):
  File "D:\Anaconda\envs\onp\lib\site-packages\wandb\util.py", line 581, in no_retry_auth
    raise CommError("Invalid or missing api_key.  Run wandb login")
wandb.errors.error.CommError: Invalid or missing api_key.  Run wandb login

During handling of the above exception, another exception occurred:

Traceback (most recent call last):
  File "D:\Anaconda\envs\onp\lib\site-packages\wandb\internal\internal_util.py", line 33, in run
    self._run()
  File "D:\Anaconda\envs\onp\lib\site-packages\wandb\internal\internal_util.py", line 60, in _run
    self._process(record)
  File "D:\Anaconda\envs\onp\lib\site-packages\wandb\internal\internal.py", line 232, in _process
    self._sm.send(record)
  File "D:\Anaconda\envs\onp\lib\site-packages\wandb\internal\sender.py", line 90, in send
    send_handler(record)
  File "D:\Anaconda\envs\onp\lib\site-packages\wandb\internal\sender.py", line 360, in send_run
    self._init_run(run, config_dict)
  File "D:\Anaconda\envs\onp\lib\site-packages\wandb\internal\sender.py", line 396, in _init_run
    commit=repo.last_commit,
  File "D:\Anaconda\envs\onp\lib\site-packages\wandb\apis\normalize.py", line 62, in wrapper
    six.reraise(CommError, CommError(message, err), sys.exc_info()[2])
  File "D:\Anaconda\envs\onp\lib\site-packages\six.py", line 702, in reraise
    raise value.with_traceback(tb)
  File "D:\Anaconda\envs\onp\lib\site-packages\wandb\apis\normalize.py", line 24, in wrapper
    return func(*args, **kwargs)
  File "D:\Anaconda\envs\onp\lib\site-packages\wandb\internal\internal_api.py", line 968, in upsert_run
    response = self.gql(mutation, variable_values=variable_values, **kwargs)
  File "D:\Anaconda\envs\onp\lib\site-packages\wandb\old\retry.py", line 105, in __call__
    if not check_retry_fn(e):
  File "D:\Anaconda\envs\onp\lib\site-packages\wandb\util.py", line 581, in no_retry_auth
    raise CommError("Invalid or missing api_key.  Run wandb login")
wandb.errors.error.CommError: Invalid or missing api_key.  Run wandb login
2024-03-01 14:03:05,379 INFO    Dummy-9   :33764 [internal.py:handle_exit():137] Internal process exited
2024-03-01 14:03:05,379 DEBUG   raven-sentry.BackgroundWorker:33764 [connectionpool.py:_new_conn():823] Starting new HTTPS connection (1): o151352.ingest.sentry.io:443
