2024-03-01 14:06:52,303 INFO    MainThread:7732 [internal.py:wandb_internal():62] W&B internal server running at pid: 7732
2024-03-01 14:06:52,310 DEBUG   HandlerThread:7732 [handler.py:handle_request():54] handle_request: check_version
2024-03-01 14:06:52,310 INFO    WriterThread:7732 [datastore.py:open_for_write():76] open: C:\Users\aplus\macbf\drones\drones\method\on-policy\onpolicy\scripts\results\MPE\simple_speaker_listener\rmappo\check\wandb\run-20240301_140651-2lq35ogm\run-2lq35ogm.wandb
2024-03-01 14:06:52,310 DEBUG   SenderThread:7732 [sender.py:send():88] send: header
2024-03-01 14:06:52,310 DEBUG   SenderThread:7732 [sender.py:send():88] send: request
2024-03-01 14:06:52,310 DEBUG   SenderThread:7732 [sender.py:send_request():97] send_request: check_version
2024-03-01 14:06:52,310 DEBUG   Thread-8  :7732 [connectionpool.py:_new_conn():823] Starting new HTTPS connection (1): pypi.org:443
2024-03-01 14:06:52,733 DEBUG   Thread-8  :7732 [connectionpool.py:_make_request():393] https://pypi.org:443 "GET /pypi/wandb/json HTTP/1.1" 200 81401
2024-03-01 14:06:52,831 DEBUG   SenderThread:7732 [sender.py:send():88] send: run
2024-03-01 14:06:52,865 DEBUG   SenderThread:7732 [util.py:is_cygwin_git():315] Failed checking if running in CYGWIN due to: FileNotFoundError(2, 'The system cannot find the file specified', None, 2, None)
2024-03-01 14:06:52,865 DEBUG   SenderThread:7732 [cmd.py:execute():719] Popen(['git', 'cat-file', '--batch-check'], cwd=C:\Users\aplus\macbf\drones\drones, universal_newlines=False, shell=None, istream=<valid stream>)
2024-03-01 14:06:52,921 DEBUG   SenderThread:7732 [connectionpool.py:_new_conn():823] Starting new HTTPS connection (1): api.wandb.ai:443
2024-03-01 14:06:53,268 DEBUG   SenderThread:7732 [connectionpool.py:_make_request():393] https://api.wandb.ai:443 "POST /graphql HTTP/1.1" 404 None
2024-03-01 14:06:53,268 ERROR   SenderThread:7732 [internal_api.py:execute():131] 404 response executing GraphQL.
2024-03-01 14:06:53,268 ERROR   SenderThread:7732 [internal_api.py:execute():132] {"errors":[{"message":"project not found","path":["upsertBucket"]}],"data":{"upsertBucket":null}}
2024-03-01 14:06:53,831 INFO    HandlerThread:7732 [handler.py:finish():267] shutting down handler
2024-03-01 14:06:53,845 INFO    WriterThread:7732 [datastore.py:close():257] close: C:\Users\aplus\macbf\drones\drones\method\on-policy\onpolicy\scripts\results\MPE\simple_speaker_listener\rmappo\check\wandb\run-20240301_140651-2lq35ogm\run-2lq35ogm.wandb
2024-03-01 14:06:53,845 ERROR   MainThread:7732 [internal.py:wandb_internal():128] Thread SenderThread:
Traceback (most recent call last):
  File "D:\Anaconda\envs\onp\lib\site-packages\wandb\old\retry.py", line 96, in __call__
    result = self._call_fn(*args, **kwargs)
  File "D:\Anaconda\envs\onp\lib\site-packages\wandb\internal\internal_api.py", line 134, in execute
    six.reraise(*sys.exc_info())
  File "D:\Anaconda\envs\onp\lib\site-packages\six.py", line 703, in reraise
    raise value
  File "D:\Anaconda\envs\onp\lib\site-packages\wandb\internal\internal_api.py", line 128, in execute
    return self.client.execute(*args, **kwargs)
  File "D:\Anaconda\envs\onp\lib\site-packages\wandb\vendor\gql-0.2.0\gql\client.py", line 52, in execute
    result = self._get_result(document, *args, **kwargs)
  File "D:\Anaconda\envs\onp\lib\site-packages\wandb\vendor\gql-0.2.0\gql\client.py", line 60, in _get_result
    return self.transport.execute(document, *args, **kwargs)
  File "D:\Anaconda\envs\onp\lib\site-packages\wandb\vendor\gql-0.2.0\gql\transport\requests.py", line 39, in execute
    request.raise_for_status()
  File "D:\Anaconda\envs\onp\lib\site-packages\requests\models.py", line 941, in raise_for_status
    raise HTTPError(http_error_msg, response=self)
requests.exceptions.HTTPError: 404 Client Error: Not Found for url: https://api.wandb.ai/graphql

During handling of the above exception, another exception occurred:

Traceback (most recent call last):
  File "D:\Anaconda\envs\onp\lib\site-packages\wandb\apis\normalize.py", line 24, in wrapper
    return func(*args, **kwargs)
  File "D:\Anaconda\envs\onp\lib\site-packages\wandb\internal\internal_api.py", line 968, in upsert_run
    response = self.gql(mutation, variable_values=variable_values, **kwargs)
  File "D:\Anaconda\envs\onp\lib\site-packages\wandb\old\retry.py", line 105, in __call__
    if not check_retry_fn(e):
  File "D:\Anaconda\envs\onp\lib\site-packages\wandb\util.py", line 585, in no_retry_auth
    raise CommError("Permission denied, ask the project owner to grant you access")
wandb.errors.error.CommError: Permission denied, ask the project owner to grant you access

During handling of the above exception, another exception occurred:

Traceback (most recent call last):
  File "D:\Anaconda\envs\onp\lib\site-packages\wandb\internal\internal_util.py", line 33, in run
    self._run()
  File "D:\Anaconda\envs\onp\lib\site-packages\wandb\internal\internal_util.py", line 60, in _run
    self._process(record)
  File "D:\Anaconda\envs\onp\lib\site-packages\wandb\internal\internal.py", line 232, in _process
    self._sm.send(record)
  File "D:\Anaconda\envs\onp\lib\site-packages\wandb\internal\sender.py", line 90, in send
    send_handler(record)
  File "D:\Anaconda\envs\onp\lib\site-packages\wandb\internal\sender.py", line 360, in send_run
    self._init_run(run, config_dict)
  File "D:\Anaconda\envs\onp\lib\site-packages\wandb\internal\sender.py", line 396, in _init_run
    commit=repo.last_commit,
  File "D:\Anaconda\envs\onp\lib\site-packages\wandb\apis\normalize.py", line 62, in wrapper
    six.reraise(CommError, CommError(message, err), sys.exc_info()[2])
  File "D:\Anaconda\envs\onp\lib\site-packages\six.py", line 702, in reraise
    raise value.with_traceback(tb)
  File "D:\Anaconda\envs\onp\lib\site-packages\wandb\apis\normalize.py", line 24, in wrapper
    return func(*args, **kwargs)
  File "D:\Anaconda\envs\onp\lib\site-packages\wandb\internal\internal_api.py", line 968, in upsert_run
    response = self.gql(mutation, variable_values=variable_values, **kwargs)
  File "D:\Anaconda\envs\onp\lib\site-packages\wandb\old\retry.py", line 105, in __call__
    if not check_retry_fn(e):
  File "D:\Anaconda\envs\onp\lib\site-packages\wandb\util.py", line 585, in no_retry_auth
    raise CommError("Permission denied, ask the project owner to grant you access")
wandb.errors.error.CommError: Permission denied, ask the project owner to grant you access
2024-03-01 14:06:53,872 INFO    Dummy-9   :7732 [internal.py:handle_exit():137] Internal process exited
2024-03-01 14:06:53,872 DEBUG   raven-sentry.BackgroundWorker:7732 [connectionpool.py:_new_conn():823] Starting new HTTPS connection (1): o151352.ingest.sentry.io:443
